[0m18:02:57.527949 [debug] [MainThread]: Sending event: {'category': 'dbt', 'action': 'invocation', 'label': 'start', 'context': [<snowplow_tracker.self_describing_json.SelfDescribingJson object at 0x11089a820>, <snowplow_tracker.self_describing_json.SelfDescribingJson object at 0x110223a60>, <snowplow_tracker.self_describing_json.SelfDescribingJson object at 0x112ff9460>]}


============================== 18:02:57.531185 | 26e608e5-6562-4e0f-a2bf-c3f74ec3291c ==============================
[0m18:02:57.531185 [info ] [MainThread]: Running with dbt=1.7.2
[0m18:02:57.531568 [debug] [MainThread]: running dbt with arguments {'printer_width': '80', 'indirect_selection': 'eager', 'write_json': 'True', 'log_cache_events': 'False', 'partial_parse': 'True', 'cache_selected_only': 'False', 'profiles_dir': '/Users/adrianpietrzykowski/.dbt', 'debug': 'False', 'version_check': 'True', 'log_path': 'logs', 'fail_fast': 'False', 'warn_error': 'None', 'use_colors': 'True', 'use_experimental_parser': 'False', 'no_print': 'None', 'quiet': 'False', 'log_format': 'default', 'introspect': 'True', 'static_parser': 'True', 'warn_error_options': 'WarnErrorOptions(include=[], exclude=[])', 'target_path': 'None', 'invocation_command': 'dbt run --select stg_stores', 'send_anonymous_usage_stats': 'True'}
[0m18:02:57.531939 [error] [MainThread]: Encountered an error:
Runtime Error
  No dbt_project.yml found at expected path /Users/adrianpietrzykowski/apps/sumup/dbt_project.yml
  Verify that each entry within packages.yml (and their transitive dependencies) contains a file named dbt_project.yml
  
[0m18:02:57.534277 [debug] [MainThread]: Resource report: {"command_name": "run", "command_wall_clock_time": 0.07643379, "process_user_time": 1.339411, "process_kernel_time": 0.179973, "process_mem_max_rss": "113229824", "command_success": false, "process_in_blocks": "0", "process_out_blocks": "0"}
[0m18:02:57.534686 [debug] [MainThread]: Command `dbt run` failed at 18:02:57.534598 after 0.08 seconds
[0m18:02:57.534936 [debug] [MainThread]: Sending event: {'category': 'dbt', 'action': 'invocation', 'label': 'end', 'context': [<snowplow_tracker.self_describing_json.SelfDescribingJson object at 0x11089a820>, <snowplow_tracker.self_describing_json.SelfDescribingJson object at 0x112fd6fa0>, <snowplow_tracker.self_describing_json.SelfDescribingJson object at 0x112fc9a60>]}
[0m18:02:57.535171 [debug] [MainThread]: Flushing usage events
[0m09:05:07.263171 [debug] [MainThread]: Sending event: {'category': 'dbt', 'action': 'invocation', 'label': 'start', 'context': [<snowplow_tracker.self_describing_json.SelfDescribingJson object at 0x10598a550>, <snowplow_tracker.self_describing_json.SelfDescribingJson object at 0x1081da520>, <snowplow_tracker.self_describing_json.SelfDescribingJson object at 0x1081eb4c0>]}


============================== 09:05:07.267345 | 551338fa-7760-4bf6-a9b4-1723cfa3a1de ==============================
[0m09:05:07.267345 [info ] [MainThread]: Running with dbt=1.7.2
[0m09:05:07.267852 [debug] [MainThread]: running dbt with arguments {'printer_width': '80', 'indirect_selection': 'eager', 'log_cache_events': 'False', 'write_json': 'True', 'partial_parse': 'True', 'cache_selected_only': 'False', 'profiles_dir': '/Users/adrianpietrzykowski/.dbt', 'debug': 'False', 'warn_error': 'None', 'log_path': 'logs', 'version_check': 'True', 'fail_fast': 'False', 'use_colors': 'True', 'use_experimental_parser': 'False', 'no_print': 'None', 'quiet': 'False', 'warn_error_options': 'WarnErrorOptions(include=[], exclude=[])', 'static_parser': 'True', 'log_format': 'default', 'introspect': 'True', 'target_path': 'None', 'invocation_command': 'dbt docs generate', 'send_anonymous_usage_stats': 'True'}
[0m09:05:07.268247 [error] [MainThread]: Encountered an error:
Runtime Error
  No dbt_project.yml found at expected path /Users/adrianpietrzykowski/Documents/GitHub/sumup-reporting/dbt_project.yml
  Verify that each entry within packages.yml (and their transitive dependencies) contains a file named dbt_project.yml
  
[0m09:05:07.277845 [debug] [MainThread]: Resource report: {"command_name": "generate", "command_wall_clock_time": 0.11206092, "process_user_time": 1.385561, "process_kernel_time": 0.244613, "process_mem_max_rss": "115589120", "command_success": false, "process_in_blocks": "0", "process_out_blocks": "0"}
[0m09:05:07.278756 [debug] [MainThread]: Command `dbt docs generate` failed at 09:05:07.278617 after 0.11 seconds
[0m09:05:07.279075 [debug] [MainThread]: Sending event: {'category': 'dbt', 'action': 'invocation', 'label': 'end', 'context': [<snowplow_tracker.self_describing_json.SelfDescribingJson object at 0x10598a550>, <snowplow_tracker.self_describing_json.SelfDescribingJson object at 0x1081ecb20>, <snowplow_tracker.self_describing_json.SelfDescribingJson object at 0x1081c9af0>]}
[0m09:05:07.279351 [debug] [MainThread]: Flushing usage events
